Internal Server Error: /v1/jwt/create/
Traceback (most recent call last):
  File "/usr/local/lib/python3.6/dist-packages/django/core/handlers/exception.py", line 34, in inner
    response = get_response(request)
  File "/usr/local/lib/python3.6/dist-packages/django/core/handlers/base.py", line 100, in _get_response
    resolver_match = resolver.resolve(request.path_info)
  File "/usr/local/lib/python3.6/dist-packages/django/urls/resolvers.py", line 536, in resolve
    for pattern in self.url_patterns:
  File "/usr/local/lib/python3.6/dist-packages/django/utils/functional.py", line 80, in __get__
    res = instance.__dict__[self.name] = self.func(instance)
  File "/usr/local/lib/python3.6/dist-packages/django/urls/resolvers.py", line 584, in url_patterns
    patterns = getattr(self.urlconf_module, "urlpatterns", self.urlconf_module)
  File "/usr/local/lib/python3.6/dist-packages/django/utils/functional.py", line 80, in __get__
    res = instance.__dict__[self.name] = self.func(instance)
  File "/usr/local/lib/python3.6/dist-packages/django/urls/resolvers.py", line 577, in urlconf_module
    return import_module(self.urlconf_name)
  File "/usr/lib/python3.6/importlib/__init__.py", line 126, in import_module
    return _bootstrap._gcd_import(name[level:], package, level)
  File "<frozen importlib._bootstrap>", line 994, in _gcd_import
  File "<frozen importlib._bootstrap>", line 971, in _find_and_load
  File "<frozen importlib._bootstrap>", line 955, in _find_and_load_unlocked
  File "<frozen importlib._bootstrap>", line 665, in _load_unlocked
  File "<frozen importlib._bootstrap_external>", line 678, in exec_module
  File "<frozen importlib._bootstrap>", line 219, in _call_with_frames_removed
  File "/applications/application/urls.py", line 4, in <module>
    from applications.users import views
ModuleNotFoundError: No module named 'applications'
Not Found: /v1/jwt/create/
Internal Server Error: /v1/jwt/create/
Traceback (most recent call last):
  File "/usr/local/lib/python3.6/dist-packages/django/db/backends/utils.py", line 84, in _execute
    return self.cursor.execute(sql, params)
psycopg2.errors.UndefinedTable: relation "users_user" does not exist
LINE 1: ...s_user"."is_active", "users_user"."is_staff" FROM "users_use...
                                                             ^


The above exception was the direct cause of the following exception:

Traceback (most recent call last):
  File "/usr/local/lib/python3.6/dist-packages/django/core/handlers/exception.py", line 34, in inner
    response = get_response(request)
  File "/usr/local/lib/python3.6/dist-packages/django/core/handlers/base.py", line 115, in _get_response
    response = self.process_exception_by_middleware(e, request)
  File "/usr/local/lib/python3.6/dist-packages/django/core/handlers/base.py", line 113, in _get_response
    response = wrapped_callback(request, *callback_args, **callback_kwargs)
  File "/usr/local/lib/python3.6/dist-packages/django/views/decorators/csrf.py", line 54, in wrapped_view
    return view_func(*args, **kwargs)
  File "/usr/local/lib/python3.6/dist-packages/django/views/generic/base.py", line 71, in view
    return self.dispatch(request, *args, **kwargs)
  File "/usr/local/lib/python3.6/dist-packages/rest_framework/views.py", line 495, in dispatch
    response = self.handle_exception(exc)
  File "/usr/local/lib/python3.6/dist-packages/rest_framework/views.py", line 455, in handle_exception
    self.raise_uncaught_exception(exc)
  File "/usr/local/lib/python3.6/dist-packages/rest_framework/views.py", line 492, in dispatch
    response = handler(request, *args, **kwargs)
  File "/usr/local/lib/python3.6/dist-packages/rest_framework_simplejwt/views.py", line 27, in post
    serializer.is_valid(raise_exception=True)
  File "/usr/local/lib/python3.6/dist-packages/rest_framework/serializers.py", line 236, in is_valid
    self._validated_data = self.run_validation(self.initial_data)
  File "/usr/local/lib/python3.6/dist-packages/rest_framework/serializers.py", line 437, in run_validation
    value = self.validate(value)
  File "/applications/users/serializer.py", line 22, in validate
    user = authenticate(**authenticate_credentials)
  File "/usr/local/lib/python3.6/dist-packages/django/contrib/auth/__init__.py", line 73, in authenticate
    user = backend.authenticate(request, **credentials)
  File "/usr/local/lib/python3.6/dist-packages/django/contrib/auth/backends.py", line 20, in authenticate
    user = UserModel._default_manager.get_by_natural_key(username)
  File "/usr/local/lib/python3.6/dist-packages/django/contrib/auth/base_user.py", line 44, in get_by_natural_key
    return self.get(**{self.model.USERNAME_FIELD: username})
  File "/usr/local/lib/python3.6/dist-packages/django/db/models/manager.py", line 82, in manager_method
    return getattr(self.get_queryset(), name)(*args, **kwargs)
  File "/usr/local/lib/python3.6/dist-packages/django/db/models/query.py", line 402, in get
    num = len(clone)
  File "/usr/local/lib/python3.6/dist-packages/django/db/models/query.py", line 256, in __len__
    self._fetch_all()
  File "/usr/local/lib/python3.6/dist-packages/django/db/models/query.py", line 1242, in _fetch_all
    self._result_cache = list(self._iterable_class(self))
  File "/usr/local/lib/python3.6/dist-packages/django/db/models/query.py", line 55, in __iter__
    results = compiler.execute_sql(chunked_fetch=self.chunked_fetch, chunk_size=self.chunk_size)
  File "/usr/local/lib/python3.6/dist-packages/django/db/models/sql/compiler.py", line 1100, in execute_sql
    cursor.execute(sql, params)
  File "/usr/local/lib/python3.6/dist-packages/django/db/backends/utils.py", line 99, in execute
    return super().execute(sql, params)
  File "/usr/local/lib/python3.6/dist-packages/django/db/backends/utils.py", line 67, in execute
    return self._execute_with_wrappers(sql, params, many=False, executor=self._execute)
  File "/usr/local/lib/python3.6/dist-packages/django/db/backends/utils.py", line 76, in _execute_with_wrappers
    return executor(sql, params, many, context)
  File "/usr/local/lib/python3.6/dist-packages/django/db/backends/utils.py", line 84, in _execute
    return self.cursor.execute(sql, params)
  File "/usr/local/lib/python3.6/dist-packages/django/db/utils.py", line 89, in __exit__
    raise dj_exc_value.with_traceback(traceback) from exc_value
  File "/usr/local/lib/python3.6/dist-packages/django/db/backends/utils.py", line 84, in _execute
    return self.cursor.execute(sql, params)
django.db.utils.ProgrammingError: relation "users_user" does not exist
LINE 1: ...s_user"."is_active", "users_user"."is_staff" FROM "users_use...
                                                             ^

Internal Server Error: /v1/users/create/
Traceback (most recent call last):
  File "/usr/local/lib/python3.6/dist-packages/django/db/backends/utils.py", line 84, in _execute
    return self.cursor.execute(sql, params)
psycopg2.errors.UndefinedTable: relation "users_user" does not exist
LINE 1: SELECT (1) AS "a" FROM "users_user" WHERE "users_user"."emai...
                               ^


The above exception was the direct cause of the following exception:

Traceback (most recent call last):
  File "/usr/local/lib/python3.6/dist-packages/django/core/handlers/exception.py", line 34, in inner
    response = get_response(request)
  File "/usr/local/lib/python3.6/dist-packages/django/core/handlers/base.py", line 115, in _get_response
    response = self.process_exception_by_middleware(e, request)
  File "/usr/local/lib/python3.6/dist-packages/django/core/handlers/base.py", line 113, in _get_response
    response = wrapped_callback(request, *callback_args, **callback_kwargs)
  File "/usr/local/lib/python3.6/dist-packages/django/views/decorators/csrf.py", line 54, in wrapped_view
    return view_func(*args, **kwargs)
  File "/usr/local/lib/python3.6/dist-packages/django/views/generic/base.py", line 71, in view
    return self.dispatch(request, *args, **kwargs)
  File "/usr/local/lib/python3.6/dist-packages/rest_framework/views.py", line 495, in dispatch
    response = self.handle_exception(exc)
  File "/usr/local/lib/python3.6/dist-packages/rest_framework/views.py", line 455, in handle_exception
    self.raise_uncaught_exception(exc)
  File "/usr/local/lib/python3.6/dist-packages/rest_framework/views.py", line 492, in dispatch
    response = handler(request, *args, **kwargs)
  File "/usr/local/lib/python3.6/dist-packages/rest_framework/generics.py", line 192, in post
    return self.create(request, *args, **kwargs)
  File "/applications/users/views.py", line 35, in create
    serializer.is_valid(raise_exception=True)
  File "/usr/local/lib/python3.6/dist-packages/rest_framework/serializers.py", line 236, in is_valid
    self._validated_data = self.run_validation(self.initial_data)
  File "/usr/local/lib/python3.6/dist-packages/rest_framework/serializers.py", line 434, in run_validation
    value = self.to_internal_value(data)
  File "/usr/local/lib/python3.6/dist-packages/rest_framework/serializers.py", line 490, in to_internal_value
    validated_value = validate_method(validated_value)
  File "/applications/users/serializer.py", line 45, in validate_email
    if user.exists():
  File "/usr/local/lib/python3.6/dist-packages/django/db/models/query.py", line 766, in exists
    return self.query.has_results(using=self.db)
  File "/usr/local/lib/python3.6/dist-packages/django/db/models/sql/query.py", line 522, in has_results
    return compiler.has_results()
  File "/usr/local/lib/python3.6/dist-packages/django/db/models/sql/compiler.py", line 1070, in has_results
    return bool(self.execute_sql(SINGLE))
  File "/usr/local/lib/python3.6/dist-packages/django/db/models/sql/compiler.py", line 1100, in execute_sql
    cursor.execute(sql, params)
  File "/usr/local/lib/python3.6/dist-packages/django/db/backends/utils.py", line 99, in execute
    return super().execute(sql, params)
  File "/usr/local/lib/python3.6/dist-packages/django/db/backends/utils.py", line 67, in execute
    return self._execute_with_wrappers(sql, params, many=False, executor=self._execute)
  File "/usr/local/lib/python3.6/dist-packages/django/db/backends/utils.py", line 76, in _execute_with_wrappers
    return executor(sql, params, many, context)
  File "/usr/local/lib/python3.6/dist-packages/django/db/backends/utils.py", line 84, in _execute
    return self.cursor.execute(sql, params)
  File "/usr/local/lib/python3.6/dist-packages/django/db/utils.py", line 89, in __exit__
    raise dj_exc_value.with_traceback(traceback) from exc_value
  File "/usr/local/lib/python3.6/dist-packages/django/db/backends/utils.py", line 84, in _execute
    return self.cursor.execute(sql, params)
django.db.utils.ProgrammingError: relation "users_user" does not exist
LINE 1: SELECT (1) AS "a" FROM "users_user" WHERE "users_user"."emai...
                               ^

Unauthorized: /v1/jwt/create/
Internal Server Error: /v1/users/create/
Traceback (most recent call last):
  File "/usr/local/lib/python3.6/dist-packages/django/core/handlers/exception.py", line 34, in inner
    response = get_response(request)
  File "/usr/local/lib/python3.6/dist-packages/django/core/handlers/base.py", line 115, in _get_response
    response = self.process_exception_by_middleware(e, request)
  File "/usr/local/lib/python3.6/dist-packages/django/core/handlers/base.py", line 113, in _get_response
    response = wrapped_callback(request, *callback_args, **callback_kwargs)
  File "/usr/local/lib/python3.6/dist-packages/django/views/decorators/csrf.py", line 54, in wrapped_view
    return view_func(*args, **kwargs)
  File "/usr/local/lib/python3.6/dist-packages/django/views/generic/base.py", line 71, in view
    return self.dispatch(request, *args, **kwargs)
  File "/usr/local/lib/python3.6/dist-packages/rest_framework/views.py", line 495, in dispatch
    response = self.handle_exception(exc)
  File "/usr/local/lib/python3.6/dist-packages/rest_framework/views.py", line 455, in handle_exception
    self.raise_uncaught_exception(exc)
  File "/usr/local/lib/python3.6/dist-packages/rest_framework/views.py", line 492, in dispatch
    response = handler(request, *args, **kwargs)
  File "/usr/local/lib/python3.6/dist-packages/rest_framework/generics.py", line 192, in post
    return self.create(request, *args, **kwargs)
  File "/applications/users/views.py", line 35, in create
    serializer.is_valid(raise_exception=True)
  File "/usr/local/lib/python3.6/dist-packages/rest_framework/serializers.py", line 236, in is_valid
    self._validated_data = self.run_validation(self.initial_data)
  File "/usr/local/lib/python3.6/dist-packages/rest_framework/serializers.py", line 434, in run_validation
    value = self.to_internal_value(data)
  File "/usr/local/lib/python3.6/dist-packages/rest_framework/serializers.py", line 490, in to_internal_value
    validated_value = validate_method(validated_value)
  File "/applications/users/serializer.py", line 50, in validate_password
    user = User(**attrs)
TypeError: ModelBase object argument after ** must be a mapping, not str
Internal Server Error: /v1/users/create/
Traceback (most recent call last):
  File "/usr/local/lib/python3.6/dist-packages/django/core/handlers/exception.py", line 34, in inner
    response = get_response(request)
  File "/usr/local/lib/python3.6/dist-packages/django/core/handlers/base.py", line 100, in _get_response
    resolver_match = resolver.resolve(request.path_info)
  File "/usr/local/lib/python3.6/dist-packages/django/urls/resolvers.py", line 536, in resolve
    for pattern in self.url_patterns:
  File "/usr/local/lib/python3.6/dist-packages/django/utils/functional.py", line 80, in __get__
    res = instance.__dict__[self.name] = self.func(instance)
  File "/usr/local/lib/python3.6/dist-packages/django/urls/resolvers.py", line 584, in url_patterns
    patterns = getattr(self.urlconf_module, "urlpatterns", self.urlconf_module)
  File "/usr/local/lib/python3.6/dist-packages/django/utils/functional.py", line 80, in __get__
    res = instance.__dict__[self.name] = self.func(instance)
  File "/usr/local/lib/python3.6/dist-packages/django/urls/resolvers.py", line 577, in urlconf_module
    return import_module(self.urlconf_name)
  File "/usr/lib/python3.6/importlib/__init__.py", line 126, in import_module
    return _bootstrap._gcd_import(name[level:], package, level)
  File "<frozen importlib._bootstrap>", line 994, in _gcd_import
  File "<frozen importlib._bootstrap>", line 971, in _find_and_load
  File "<frozen importlib._bootstrap>", line 955, in _find_and_load_unlocked
  File "<frozen importlib._bootstrap>", line 665, in _load_unlocked
  File "<frozen importlib._bootstrap_external>", line 678, in exec_module
  File "<frozen importlib._bootstrap>", line 219, in _call_with_frames_removed
  File "/applications/application/urls.py", line 4, in <module>
    from applications.users import views
ModuleNotFoundError: No module named 'applications'
Internal Server Error: /v1/jwt/create/
Traceback (most recent call last):
  File "/usr/local/lib/python3.6/dist-packages/django/core/handlers/exception.py", line 34, in inner
    response = get_response(request)
  File "/usr/local/lib/python3.6/dist-packages/django/core/handlers/base.py", line 100, in _get_response
    resolver_match = resolver.resolve(request.path_info)
  File "/usr/local/lib/python3.6/dist-packages/django/urls/resolvers.py", line 536, in resolve
    for pattern in self.url_patterns:
  File "/usr/local/lib/python3.6/dist-packages/django/utils/functional.py", line 80, in __get__
    res = instance.__dict__[self.name] = self.func(instance)
  File "/usr/local/lib/python3.6/dist-packages/django/urls/resolvers.py", line 584, in url_patterns
    patterns = getattr(self.urlconf_module, "urlpatterns", self.urlconf_module)
  File "/usr/local/lib/python3.6/dist-packages/django/utils/functional.py", line 80, in __get__
    res = instance.__dict__[self.name] = self.func(instance)
  File "/usr/local/lib/python3.6/dist-packages/django/urls/resolvers.py", line 577, in urlconf_module
    return import_module(self.urlconf_name)
  File "/usr/lib/python3.6/importlib/__init__.py", line 126, in import_module
    return _bootstrap._gcd_import(name[level:], package, level)
  File "<frozen importlib._bootstrap>", line 994, in _gcd_import
  File "<frozen importlib._bootstrap>", line 971, in _find_and_load
  File "<frozen importlib._bootstrap>", line 955, in _find_and_load_unlocked
  File "<frozen importlib._bootstrap>", line 665, in _load_unlocked
  File "<frozen importlib._bootstrap_external>", line 678, in exec_module
  File "<frozen importlib._bootstrap>", line 219, in _call_with_frames_removed
  File "/applications/application/urls.py", line 4, in <module>
    from applications.users import views
ModuleNotFoundError: No module named 'applications'
Unauthorized: /v1/jwt/create/
Unauthorized: /v1/jwt/create/
Internal Server Error: /v1/users/create/
Traceback (most recent call last):
  File "/usr/local/lib/python3.6/dist-packages/django/core/handlers/exception.py", line 34, in inner
    response = get_response(request)
  File "/usr/local/lib/python3.6/dist-packages/django/core/handlers/base.py", line 115, in _get_response
    response = self.process_exception_by_middleware(e, request)
  File "/usr/local/lib/python3.6/dist-packages/django/core/handlers/base.py", line 113, in _get_response
    response = wrapped_callback(request, *callback_args, **callback_kwargs)
  File "/usr/local/lib/python3.6/dist-packages/django/views/decorators/csrf.py", line 54, in wrapped_view
    return view_func(*args, **kwargs)
  File "/usr/local/lib/python3.6/dist-packages/django/views/generic/base.py", line 71, in view
    return self.dispatch(request, *args, **kwargs)
  File "/usr/local/lib/python3.6/dist-packages/rest_framework/views.py", line 495, in dispatch
    response = self.handle_exception(exc)
  File "/usr/local/lib/python3.6/dist-packages/rest_framework/views.py", line 455, in handle_exception
    self.raise_uncaught_exception(exc)
  File "/usr/local/lib/python3.6/dist-packages/rest_framework/views.py", line 492, in dispatch
    response = handler(request, *args, **kwargs)
  File "/usr/local/lib/python3.6/dist-packages/rest_framework/generics.py", line 192, in post
    return self.create(request, *args, **kwargs)
  File "/applications/users/views.py", line 35, in create
    serializer.is_valid(raise_exception=True)
  File "/usr/local/lib/python3.6/dist-packages/rest_framework/serializers.py", line 236, in is_valid
    self._validated_data = self.run_validation(self.initial_data)
  File "/usr/local/lib/python3.6/dist-packages/rest_framework/serializers.py", line 434, in run_validation
    value = self.to_internal_value(data)
  File "/usr/local/lib/python3.6/dist-packages/rest_framework/serializers.py", line 490, in to_internal_value
    validated_value = validate_method(validated_value)
  File "/applications/users/serializer.py", line 50, in validate_password
    user = User(**attrs)
TypeError: ModelBase object argument after ** must be a mapping, not str
Internal Server Error: /v1/users/create/
Traceback (most recent call last):
  File "/usr/local/lib/python3.6/dist-packages/django/core/handlers/exception.py", line 34, in inner
    response = get_response(request)
  File "/usr/local/lib/python3.6/dist-packages/django/core/handlers/base.py", line 100, in _get_response
    resolver_match = resolver.resolve(request.path_info)
  File "/usr/local/lib/python3.6/dist-packages/django/urls/resolvers.py", line 536, in resolve
    for pattern in self.url_patterns:
  File "/usr/local/lib/python3.6/dist-packages/django/utils/functional.py", line 80, in __get__
    res = instance.__dict__[self.name] = self.func(instance)
  File "/usr/local/lib/python3.6/dist-packages/django/urls/resolvers.py", line 584, in url_patterns
    patterns = getattr(self.urlconf_module, "urlpatterns", self.urlconf_module)
  File "/usr/local/lib/python3.6/dist-packages/django/utils/functional.py", line 80, in __get__
    res = instance.__dict__[self.name] = self.func(instance)
  File "/usr/local/lib/python3.6/dist-packages/django/urls/resolvers.py", line 577, in urlconf_module
    return import_module(self.urlconf_name)
  File "/usr/lib/python3.6/importlib/__init__.py", line 126, in import_module
    return _bootstrap._gcd_import(name[level:], package, level)
  File "<frozen importlib._bootstrap>", line 994, in _gcd_import
  File "<frozen importlib._bootstrap>", line 971, in _find_and_load
  File "<frozen importlib._bootstrap>", line 955, in _find_and_load_unlocked
  File "<frozen importlib._bootstrap>", line 665, in _load_unlocked
  File "<frozen importlib._bootstrap_external>", line 678, in exec_module
  File "<frozen importlib._bootstrap>", line 219, in _call_with_frames_removed
  File "/applications/application/urls.py", line 4, in <module>
    from users import views
  File "/applications/users/views.py", line 6, in <module>
    from djoser.views import UserCreateView as DjoserUserCreateView
  File "/usr/local/lib/python3.6/dist-packages/djoser/views.py", line 85, in <module>
    class UserCreateView(UserCreateMixin, generics.CreateAPIView):
  File "/usr/local/lib/python3.6/dist-packages/djoser/views.py", line 89, in UserCreateView
    serializer_class = settings.SERIALIZERS.user_create
  File "/usr/local/lib/python3.6/dist-packages/djoser/conf.py", line 18, in __getattribute__
    val = import_string(val)
  File "/usr/local/lib/python3.6/dist-packages/django/utils/module_loading.py", line 17, in import_string
    module = import_module(module_path)
  File "/usr/lib/python3.6/importlib/__init__.py", line 126, in import_module
    return _bootstrap._gcd_import(name[level:], package, level)
ModuleNotFoundError: No module named 'apps'
Internal Server Error: /v1/users/create/
Traceback (most recent call last):
  File "/usr/local/lib/python3.6/dist-packages/django/core/handlers/exception.py", line 34, in inner
    response = get_response(request)
  File "/usr/local/lib/python3.6/dist-packages/django/core/handlers/base.py", line 100, in _get_response
    resolver_match = resolver.resolve(request.path_info)
  File "/usr/local/lib/python3.6/dist-packages/django/urls/resolvers.py", line 536, in resolve
    for pattern in self.url_patterns:
  File "/usr/local/lib/python3.6/dist-packages/django/utils/functional.py", line 80, in __get__
    res = instance.__dict__[self.name] = self.func(instance)
  File "/usr/local/lib/python3.6/dist-packages/django/urls/resolvers.py", line 584, in url_patterns
    patterns = getattr(self.urlconf_module, "urlpatterns", self.urlconf_module)
  File "/usr/local/lib/python3.6/dist-packages/django/utils/functional.py", line 80, in __get__
    res = instance.__dict__[self.name] = self.func(instance)
  File "/usr/local/lib/python3.6/dist-packages/django/urls/resolvers.py", line 577, in urlconf_module
    return import_module(self.urlconf_name)
  File "/usr/lib/python3.6/importlib/__init__.py", line 126, in import_module
    return _bootstrap._gcd_import(name[level:], package, level)
  File "<frozen importlib._bootstrap>", line 994, in _gcd_import
  File "<frozen importlib._bootstrap>", line 971, in _find_and_load
  File "<frozen importlib._bootstrap>", line 955, in _find_and_load_unlocked
  File "<frozen importlib._bootstrap>", line 665, in _load_unlocked
  File "<frozen importlib._bootstrap_external>", line 678, in exec_module
  File "<frozen importlib._bootstrap>", line 219, in _call_with_frames_removed
  File "/applications/application/urls.py", line 4, in <module>
    from users import views
  File "/applications/users/views.py", line 6, in <module>
    from djoser.views import UserCreateView as DjoserUserCreateView
  File "/usr/local/lib/python3.6/dist-packages/djoser/views.py", line 85, in <module>
    class UserCreateView(UserCreateMixin, generics.CreateAPIView):
  File "/usr/local/lib/python3.6/dist-packages/djoser/views.py", line 89, in UserCreateView
    serializer_class = settings.SERIALIZERS.user_create
  File "/usr/local/lib/python3.6/dist-packages/djoser/conf.py", line 18, in __getattribute__
    val = import_string(val)
  File "/usr/local/lib/python3.6/dist-packages/django/utils/module_loading.py", line 17, in import_string
    module = import_module(module_path)
  File "/usr/lib/python3.6/importlib/__init__.py", line 126, in import_module
    return _bootstrap._gcd_import(name[level:], package, level)
ModuleNotFoundError: No module named 'user'
Internal Server Error: /v1/users/create/
Traceback (most recent call last):
  File "/usr/local/lib/python3.6/dist-packages/django/core/handlers/exception.py", line 34, in inner
    response = get_response(request)
  File "/usr/local/lib/python3.6/dist-packages/django/core/handlers/base.py", line 115, in _get_response
    response = self.process_exception_by_middleware(e, request)
  File "/usr/local/lib/python3.6/dist-packages/django/core/handlers/base.py", line 113, in _get_response
    response = wrapped_callback(request, *callback_args, **callback_kwargs)
  File "/usr/local/lib/python3.6/dist-packages/django/views/decorators/csrf.py", line 54, in wrapped_view
    return view_func(*args, **kwargs)
  File "/usr/local/lib/python3.6/dist-packages/django/views/generic/base.py", line 71, in view
    return self.dispatch(request, *args, **kwargs)
  File "/usr/local/lib/python3.6/dist-packages/rest_framework/views.py", line 495, in dispatch
    response = self.handle_exception(exc)
  File "/usr/local/lib/python3.6/dist-packages/rest_framework/views.py", line 455, in handle_exception
    self.raise_uncaught_exception(exc)
  File "/usr/local/lib/python3.6/dist-packages/rest_framework/views.py", line 492, in dispatch
    response = handler(request, *args, **kwargs)
  File "/usr/local/lib/python3.6/dist-packages/rest_framework/generics.py", line 192, in post
    return self.create(request, *args, **kwargs)
  File "/applications/users/views.py", line 35, in create
    serializer.is_valid(raise_exception=True)
  File "/usr/local/lib/python3.6/dist-packages/rest_framework/serializers.py", line 236, in is_valid
    self._validated_data = self.run_validation(self.initial_data)
  File "/usr/local/lib/python3.6/dist-packages/rest_framework/serializers.py", line 434, in run_validation
    value = self.to_internal_value(data)
  File "/usr/local/lib/python3.6/dist-packages/rest_framework/serializers.py", line 490, in to_internal_value
    validated_value = validate_method(validated_value)
  File "/applications/users/serializer.py", line 50, in validate_password
    user = User(*attrs)
  File "/usr/local/lib/python3.6/dist-packages/django/db/models/base.py", line 419, in __init__
    raise IndexError("Number of args exceeds number of fields")
IndexError: Number of args exceeds number of fields
Internal Server Error: /v1/users/create/
Traceback (most recent call last):
  File "/usr/local/lib/python3.6/dist-packages/django/core/handlers/exception.py", line 34, in inner
    response = get_response(request)
  File "/usr/local/lib/python3.6/dist-packages/django/core/handlers/base.py", line 115, in _get_response
    response = self.process_exception_by_middleware(e, request)
  File "/usr/local/lib/python3.6/dist-packages/django/core/handlers/base.py", line 113, in _get_response
    response = wrapped_callback(request, *callback_args, **callback_kwargs)
  File "/usr/local/lib/python3.6/dist-packages/django/views/decorators/csrf.py", line 54, in wrapped_view
    return view_func(*args, **kwargs)
  File "/usr/local/lib/python3.6/dist-packages/django/views/generic/base.py", line 71, in view
    return self.dispatch(request, *args, **kwargs)
  File "/usr/local/lib/python3.6/dist-packages/rest_framework/views.py", line 495, in dispatch
    response = self.handle_exception(exc)
  File "/usr/local/lib/python3.6/dist-packages/rest_framework/views.py", line 455, in handle_exception
    self.raise_uncaught_exception(exc)
  File "/usr/local/lib/python3.6/dist-packages/rest_framework/views.py", line 492, in dispatch
    response = handler(request, *args, **kwargs)
  File "/usr/local/lib/python3.6/dist-packages/rest_framework/generics.py", line 192, in post
    return self.create(request, *args, **kwargs)
  File "/applications/users/views.py", line 35, in create
    serializer.is_valid(raise_exception=True)
  File "/usr/local/lib/python3.6/dist-packages/rest_framework/serializers.py", line 236, in is_valid
    self._validated_data = self.run_validation(self.initial_data)
  File "/usr/local/lib/python3.6/dist-packages/rest_framework/serializers.py", line 434, in run_validation
    value = self.to_internal_value(data)
  File "/usr/local/lib/python3.6/dist-packages/rest_framework/serializers.py", line 490, in to_internal_value
    validated_value = validate_method(validated_value)
  File "/applications/users/serializer.py", line 50, in validate_password
    user = User(**attrs)
TypeError: ModelBase object argument after ** must be a mapping, not str
Internal Server Error: /v1/users/create/
Traceback (most recent call last):
  File "/usr/local/lib/python3.6/dist-packages/django/core/handlers/exception.py", line 34, in inner
    response = get_response(request)
  File "/usr/local/lib/python3.6/dist-packages/django/core/handlers/base.py", line 115, in _get_response
    response = self.process_exception_by_middleware(e, request)
  File "/usr/local/lib/python3.6/dist-packages/django/core/handlers/base.py", line 113, in _get_response
    response = wrapped_callback(request, *callback_args, **callback_kwargs)
  File "/usr/local/lib/python3.6/dist-packages/django/views/decorators/csrf.py", line 54, in wrapped_view
    return view_func(*args, **kwargs)
  File "/usr/local/lib/python3.6/dist-packages/django/views/generic/base.py", line 71, in view
    return self.dispatch(request, *args, **kwargs)
  File "/usr/local/lib/python3.6/dist-packages/rest_framework/views.py", line 495, in dispatch
    response = self.handle_exception(exc)
  File "/usr/local/lib/python3.6/dist-packages/rest_framework/views.py", line 455, in handle_exception
    self.raise_uncaught_exception(exc)
  File "/usr/local/lib/python3.6/dist-packages/rest_framework/views.py", line 492, in dispatch
    response = handler(request, *args, **kwargs)
  File "/usr/local/lib/python3.6/dist-packages/rest_framework/generics.py", line 192, in post
    return self.create(request, *args, **kwargs)
  File "/applications/users/views.py", line 35, in create
    serializer.is_valid(raise_exception=True)
  File "/usr/local/lib/python3.6/dist-packages/rest_framework/serializers.py", line 236, in is_valid
    self._validated_data = self.run_validation(self.initial_data)
  File "/usr/local/lib/python3.6/dist-packages/rest_framework/serializers.py", line 434, in run_validation
    value = self.to_internal_value(data)
  File "/usr/local/lib/python3.6/dist-packages/rest_framework/serializers.py", line 490, in to_internal_value
    validated_value = validate_method(validated_value)
  File "/applications/users/serializer.py", line 50, in validate_password
    user = User(*attrs)
  File "/usr/local/lib/python3.6/dist-packages/django/db/models/base.py", line 419, in __init__
    raise IndexError("Number of args exceeds number of fields")
IndexError: Number of args exceeds number of fields
Internal Server Error: /v1/users/create/
Traceback (most recent call last):
  File "/usr/local/lib/python3.6/dist-packages/django/core/handlers/exception.py", line 34, in inner
    response = get_response(request)
  File "/usr/local/lib/python3.6/dist-packages/django/core/handlers/base.py", line 115, in _get_response
    response = self.process_exception_by_middleware(e, request)
  File "/usr/local/lib/python3.6/dist-packages/django/core/handlers/base.py", line 113, in _get_response
    response = wrapped_callback(request, *callback_args, **callback_kwargs)
  File "/usr/local/lib/python3.6/dist-packages/django/views/decorators/csrf.py", line 54, in wrapped_view
    return view_func(*args, **kwargs)
  File "/usr/local/lib/python3.6/dist-packages/django/views/generic/base.py", line 71, in view
    return self.dispatch(request, *args, **kwargs)
  File "/usr/local/lib/python3.6/dist-packages/rest_framework/views.py", line 495, in dispatch
    response = self.handle_exception(exc)
  File "/usr/local/lib/python3.6/dist-packages/rest_framework/views.py", line 455, in handle_exception
    self.raise_uncaught_exception(exc)
  File "/usr/local/lib/python3.6/dist-packages/rest_framework/views.py", line 492, in dispatch
    response = handler(request, *args, **kwargs)
  File "/usr/local/lib/python3.6/dist-packages/rest_framework/generics.py", line 192, in post
    return self.create(request, *args, **kwargs)
  File "/applications/users/views.py", line 35, in create
    serializer.is_valid(raise_exception=True)
  File "/usr/local/lib/python3.6/dist-packages/rest_framework/serializers.py", line 236, in is_valid
    self._validated_data = self.run_validation(self.initial_data)
  File "/usr/local/lib/python3.6/dist-packages/rest_framework/serializers.py", line 434, in run_validation
    value = self.to_internal_value(data)
  File "/usr/local/lib/python3.6/dist-packages/rest_framework/serializers.py", line 490, in to_internal_value
    validated_value = validate_method(validated_value)
  File "/applications/users/serializer.py", line 50, in validate_password
    user = User(*attrs)
  File "/usr/local/lib/python3.6/dist-packages/django/db/models/base.py", line 419, in __init__
    raise IndexError("Number of args exceeds number of fields")
IndexError: Number of args exceeds number of fields
Internal Server Error: /v1/users/create/
Traceback (most recent call last):
  File "/usr/local/lib/python3.6/dist-packages/django/core/handlers/exception.py", line 34, in inner
    response = get_response(request)
  File "/usr/local/lib/python3.6/dist-packages/django/core/handlers/base.py", line 115, in _get_response
    response = self.process_exception_by_middleware(e, request)
  File "/usr/local/lib/python3.6/dist-packages/django/core/handlers/base.py", line 113, in _get_response
    response = wrapped_callback(request, *callback_args, **callback_kwargs)
  File "/usr/local/lib/python3.6/dist-packages/django/views/decorators/csrf.py", line 54, in wrapped_view
    return view_func(*args, **kwargs)
  File "/usr/local/lib/python3.6/dist-packages/django/views/generic/base.py", line 71, in view
    return self.dispatch(request, *args, **kwargs)
  File "/usr/local/lib/python3.6/dist-packages/rest_framework/views.py", line 495, in dispatch
    response = self.handle_exception(exc)
  File "/usr/local/lib/python3.6/dist-packages/rest_framework/views.py", line 455, in handle_exception
    self.raise_uncaught_exception(exc)
  File "/usr/local/lib/python3.6/dist-packages/rest_framework/views.py", line 492, in dispatch
    response = handler(request, *args, **kwargs)
  File "/usr/local/lib/python3.6/dist-packages/rest_framework/generics.py", line 192, in post
    return self.create(request, *args, **kwargs)
  File "/applications/users/views.py", line 35, in create
    serializer.is_valid(raise_exception=True)
  File "/usr/local/lib/python3.6/dist-packages/rest_framework/serializers.py", line 236, in is_valid
    self._validated_data = self.run_validation(self.initial_data)
  File "/usr/local/lib/python3.6/dist-packages/rest_framework/serializers.py", line 434, in run_validation
    value = self.to_internal_value(data)
  File "/usr/local/lib/python3.6/dist-packages/rest_framework/serializers.py", line 490, in to_internal_value
    validated_value = validate_method(validated_value)
  File "/applications/users/serializer.py", line 50, in validate_password
    user = User.objects.get(email=attrs.get('email'))
AttributeError: 'str' object has no attribute 'get'
Internal Server Error: /v1/users/create/
Traceback (most recent call last):
  File "/usr/local/lib/python3.6/dist-packages/django/core/handlers/exception.py", line 34, in inner
    response = get_response(request)
  File "/usr/local/lib/python3.6/dist-packages/django/core/handlers/base.py", line 115, in _get_response
    response = self.process_exception_by_middleware(e, request)
  File "/usr/local/lib/python3.6/dist-packages/django/core/handlers/base.py", line 113, in _get_response
    response = wrapped_callback(request, *callback_args, **callback_kwargs)
  File "/usr/local/lib/python3.6/dist-packages/django/views/decorators/csrf.py", line 54, in wrapped_view
    return view_func(*args, **kwargs)
  File "/usr/local/lib/python3.6/dist-packages/django/views/generic/base.py", line 71, in view
    return self.dispatch(request, *args, **kwargs)
  File "/usr/local/lib/python3.6/dist-packages/rest_framework/views.py", line 495, in dispatch
    response = self.handle_exception(exc)
  File "/usr/local/lib/python3.6/dist-packages/rest_framework/views.py", line 455, in handle_exception
    self.raise_uncaught_exception(exc)
  File "/usr/local/lib/python3.6/dist-packages/rest_framework/views.py", line 492, in dispatch
    response = handler(request, *args, **kwargs)
  File "/usr/local/lib/python3.6/dist-packages/rest_framework/generics.py", line 192, in post
    return self.create(request, *args, **kwargs)
  File "/applications/users/views.py", line 35, in create
    serializer.is_valid(raise_exception=True)
  File "/usr/local/lib/python3.6/dist-packages/rest_framework/serializers.py", line 236, in is_valid
    self._validated_data = self.run_validation(self.initial_data)
  File "/usr/local/lib/python3.6/dist-packages/rest_framework/serializers.py", line 434, in run_validation
    value = self.to_internal_value(data)
  File "/usr/local/lib/python3.6/dist-packages/rest_framework/serializers.py", line 490, in to_internal_value
    validated_value = validate_method(validated_value)
  File "/applications/users/serializer.py", line 51, in validate_password
    user = User(**attrs)
TypeError: ModelBase object argument after ** must be a mapping, not str
Internal Server Error: /v1/users/create/
Traceback (most recent call last):
  File "/usr/local/lib/python3.6/dist-packages/django/core/handlers/exception.py", line 34, in inner
    response = get_response(request)
  File "/usr/local/lib/python3.6/dist-packages/django/core/handlers/base.py", line 115, in _get_response
    response = self.process_exception_by_middleware(e, request)
  File "/usr/local/lib/python3.6/dist-packages/django/core/handlers/base.py", line 113, in _get_response
    response = wrapped_callback(request, *callback_args, **callback_kwargs)
  File "/usr/local/lib/python3.6/dist-packages/django/views/decorators/csrf.py", line 54, in wrapped_view
    return view_func(*args, **kwargs)
  File "/usr/local/lib/python3.6/dist-packages/django/views/generic/base.py", line 71, in view
    return self.dispatch(request, *args, **kwargs)
  File "/usr/local/lib/python3.6/dist-packages/rest_framework/views.py", line 495, in dispatch
    response = self.handle_exception(exc)
  File "/usr/local/lib/python3.6/dist-packages/rest_framework/views.py", line 455, in handle_exception
    self.raise_uncaught_exception(exc)
  File "/usr/local/lib/python3.6/dist-packages/rest_framework/views.py", line 492, in dispatch
    response = handler(request, *args, **kwargs)
  File "/usr/local/lib/python3.6/dist-packages/rest_framework/generics.py", line 192, in post
    return self.create(request, *args, **kwargs)
  File "/applications/users/views.py", line 35, in create
    serializer.is_valid(raise_exception=True)
  File "/usr/local/lib/python3.6/dist-packages/rest_framework/serializers.py", line 236, in is_valid
    self._validated_data = self.run_validation(self.initial_data)
  File "/usr/local/lib/python3.6/dist-packages/rest_framework/serializers.py", line 434, in run_validation
    value = self.to_internal_value(data)
  File "/usr/local/lib/python3.6/dist-packages/rest_framework/serializers.py", line 490, in to_internal_value
    validated_value = validate_method(validated_value)
  File "/applications/users/serializer.py", line 52, in validate_password
    user = User(**attrs)
TypeError: ModelBase object argument after ** must be a mapping, not str
Internal Server Error: /v1/users/create/
Traceback (most recent call last):
  File "/usr/local/lib/python3.6/dist-packages/django/core/handlers/exception.py", line 34, in inner
    response = get_response(request)
  File "/usr/local/lib/python3.6/dist-packages/django/core/handlers/base.py", line 115, in _get_response
    response = self.process_exception_by_middleware(e, request)
  File "/usr/local/lib/python3.6/dist-packages/django/core/handlers/base.py", line 113, in _get_response
    response = wrapped_callback(request, *callback_args, **callback_kwargs)
  File "/usr/local/lib/python3.6/dist-packages/django/views/decorators/csrf.py", line 54, in wrapped_view
    return view_func(*args, **kwargs)
  File "/usr/local/lib/python3.6/dist-packages/django/views/generic/base.py", line 71, in view
    return self.dispatch(request, *args, **kwargs)
  File "/usr/local/lib/python3.6/dist-packages/rest_framework/views.py", line 495, in dispatch
    response = self.handle_exception(exc)
  File "/usr/local/lib/python3.6/dist-packages/rest_framework/views.py", line 455, in handle_exception
    self.raise_uncaught_exception(exc)
  File "/usr/local/lib/python3.6/dist-packages/rest_framework/views.py", line 492, in dispatch
    response = handler(request, *args, **kwargs)
  File "/usr/local/lib/python3.6/dist-packages/rest_framework/generics.py", line 192, in post
    return self.create(request, *args, **kwargs)
  File "/applications/users/views.py", line 35, in create
    serializer.is_valid(raise_exception=True)
  File "/usr/local/lib/python3.6/dist-packages/rest_framework/serializers.py", line 236, in is_valid
    self._validated_data = self.run_validation(self.initial_data)
  File "/usr/local/lib/python3.6/dist-packages/rest_framework/serializers.py", line 434, in run_validation
    value = self.to_internal_value(data)
  File "/usr/local/lib/python3.6/dist-packages/rest_framework/serializers.py", line 490, in to_internal_value
    validated_value = validate_method(validated_value)
  File "/applications/users/serializer.py", line 52, in validate_password
    user = User(*attrs)
  File "/usr/local/lib/python3.6/dist-packages/django/db/models/base.py", line 419, in __init__
    raise IndexError("Number of args exceeds number of fields")
IndexError: Number of args exceeds number of fields
Internal Server Error: /v1/users/create/
Traceback (most recent call last):
  File "/usr/local/lib/python3.6/dist-packages/django/core/handlers/exception.py", line 34, in inner
    response = get_response(request)
  File "/usr/local/lib/python3.6/dist-packages/django/core/handlers/base.py", line 115, in _get_response
    response = self.process_exception_by_middleware(e, request)
  File "/usr/local/lib/python3.6/dist-packages/django/core/handlers/base.py", line 113, in _get_response
    response = wrapped_callback(request, *callback_args, **callback_kwargs)
  File "/usr/local/lib/python3.6/dist-packages/django/views/decorators/csrf.py", line 54, in wrapped_view
    return view_func(*args, **kwargs)
  File "/usr/local/lib/python3.6/dist-packages/django/views/generic/base.py", line 71, in view
    return self.dispatch(request, *args, **kwargs)
  File "/usr/local/lib/python3.6/dist-packages/rest_framework/views.py", line 495, in dispatch
    response = self.handle_exception(exc)
  File "/usr/local/lib/python3.6/dist-packages/rest_framework/views.py", line 455, in handle_exception
    self.raise_uncaught_exception(exc)
  File "/usr/local/lib/python3.6/dist-packages/rest_framework/views.py", line 492, in dispatch
    response = handler(request, *args, **kwargs)
  File "/usr/local/lib/python3.6/dist-packages/rest_framework/generics.py", line 192, in post
    return self.create(request, *args, **kwargs)
  File "/applications/users/views.py", line 35, in create
    serializer.is_valid(raise_exception=True)
  File "/usr/local/lib/python3.6/dist-packages/rest_framework/serializers.py", line 236, in is_valid
    self._validated_data = self.run_validation(self.initial_data)
  File "/usr/local/lib/python3.6/dist-packages/rest_framework/serializers.py", line 434, in run_validation
    value = self.to_internal_value(data)
  File "/usr/local/lib/python3.6/dist-packages/rest_framework/serializers.py", line 490, in to_internal_value
    validated_value = validate_method(validated_value)
  File "/applications/users/serializer.py", line 50, in validate_password
    user = User(email=attrs["email"], password=attrs["password"])
TypeError: string indices must be integers
Internal Server Error: /v1/users/create/
Traceback (most recent call last):
  File "/usr/local/lib/python3.6/dist-packages/django/core/handlers/exception.py", line 34, in inner
    response = get_response(request)
  File "/usr/local/lib/python3.6/dist-packages/django/core/handlers/base.py", line 115, in _get_response
    response = self.process_exception_by_middleware(e, request)
  File "/usr/local/lib/python3.6/dist-packages/django/core/handlers/base.py", line 113, in _get_response
    response = wrapped_callback(request, *callback_args, **callback_kwargs)
  File "/usr/local/lib/python3.6/dist-packages/django/views/decorators/csrf.py", line 54, in wrapped_view
    return view_func(*args, **kwargs)
  File "/usr/local/lib/python3.6/dist-packages/django/views/generic/base.py", line 71, in view
    return self.dispatch(request, *args, **kwargs)
  File "/usr/local/lib/python3.6/dist-packages/rest_framework/views.py", line 495, in dispatch
    response = self.handle_exception(exc)
  File "/usr/local/lib/python3.6/dist-packages/rest_framework/views.py", line 455, in handle_exception
    self.raise_uncaught_exception(exc)
  File "/usr/local/lib/python3.6/dist-packages/rest_framework/views.py", line 492, in dispatch
    response = handler(request, *args, **kwargs)
  File "/usr/local/lib/python3.6/dist-packages/rest_framework/generics.py", line 192, in post
    return self.create(request, *args, **kwargs)
  File "/applications/users/views.py", line 39, in create
    self.perform_create(serializer)
  File "/applications/users/views.py", line 33, in perform_create
    settings.EMAIL.activation(self.request, context).send(to)
  File "/usr/local/lib/python3.6/dist-packages/templated_mail/mail.py", line 78, in send
    super(BaseEmailMessage, self).send(*args, **kwargs)
  File "/usr/local/lib/python3.6/dist-packages/django/core/mail/message.py", line 287, in send
    if not self.recipients():
  File "/usr/local/lib/python3.6/dist-packages/django/core/mail/message.py", line 283, in recipients
    return [email for email in (self.to + self.cc + self.bcc) if email]
TypeError: must be str, not list
Bad Request: /v1/users/create/
Internal Server Error: /v1/users/create/
Traceback (most recent call last):
  File "/usr/local/lib/python3.6/dist-packages/django/core/handlers/exception.py", line 34, in inner
    response = get_response(request)
  File "/usr/local/lib/python3.6/dist-packages/django/core/handlers/base.py", line 115, in _get_response
    response = self.process_exception_by_middleware(e, request)
  File "/usr/local/lib/python3.6/dist-packages/django/core/handlers/base.py", line 113, in _get_response
    response = wrapped_callback(request, *callback_args, **callback_kwargs)
  File "/usr/local/lib/python3.6/dist-packages/django/views/decorators/csrf.py", line 54, in wrapped_view
    return view_func(*args, **kwargs)
  File "/usr/local/lib/python3.6/dist-packages/django/views/generic/base.py", line 71, in view
    return self.dispatch(request, *args, **kwargs)
  File "/usr/local/lib/python3.6/dist-packages/rest_framework/views.py", line 495, in dispatch
    response = self.handle_exception(exc)
  File "/usr/local/lib/python3.6/dist-packages/rest_framework/views.py", line 455, in handle_exception
    self.raise_uncaught_exception(exc)
  File "/usr/local/lib/python3.6/dist-packages/rest_framework/views.py", line 492, in dispatch
    response = handler(request, *args, **kwargs)
  File "/usr/local/lib/python3.6/dist-packages/rest_framework/generics.py", line 192, in post
    return self.create(request, *args, **kwargs)
  File "/applications/users/views.py", line 38, in create
    self.perform_create(serializer)
  File "/applications/users/views.py", line 33, in perform_create
    settings.EMAIL.activation(self.request, context).send(to)
  File "/usr/local/lib/python3.6/dist-packages/djoser/conf.py", line 18, in __getattribute__
    val = import_string(val)
  File "/usr/local/lib/python3.6/dist-packages/django/utils/module_loading.py", line 17, in import_string
    module = import_module(module_path)
  File "/usr/lib/python3.6/importlib/__init__.py", line 126, in import_module
    return _bootstrap._gcd_import(name[level:], package, level)
  File "<frozen importlib._bootstrap>", line 994, in _gcd_import
  File "<frozen importlib._bootstrap>", line 971, in _find_and_load
  File "<frozen importlib._bootstrap>", line 941, in _find_and_load_unlocked
  File "<frozen importlib._bootstrap>", line 219, in _call_with_frames_removed
  File "<frozen importlib._bootstrap>", line 994, in _gcd_import
  File "<frozen importlib._bootstrap>", line 971, in _find_and_load
  File "<frozen importlib._bootstrap>", line 953, in _find_and_load_unlocked
ModuleNotFoundError: No module named 'emails.'
Bad Request: /v1/users/create/
Internal Server Error: /v1/users/create/
Traceback (most recent call last):
  File "/usr/local/lib/python3.6/dist-packages/django/core/handlers/exception.py", line 34, in inner
    response = get_response(request)
  File "/usr/local/lib/python3.6/dist-packages/django/core/handlers/base.py", line 115, in _get_response
    response = self.process_exception_by_middleware(e, request)
  File "/usr/local/lib/python3.6/dist-packages/django/core/handlers/base.py", line 113, in _get_response
    response = wrapped_callback(request, *callback_args, **callback_kwargs)
  File "/usr/local/lib/python3.6/dist-packages/django/views/decorators/csrf.py", line 54, in wrapped_view
    return view_func(*args, **kwargs)
  File "/usr/local/lib/python3.6/dist-packages/django/views/generic/base.py", line 71, in view
    return self.dispatch(request, *args, **kwargs)
  File "/usr/local/lib/python3.6/dist-packages/rest_framework/views.py", line 495, in dispatch
    response = self.handle_exception(exc)
  File "/usr/local/lib/python3.6/dist-packages/rest_framework/views.py", line 455, in handle_exception
    self.raise_uncaught_exception(exc)
  File "/usr/local/lib/python3.6/dist-packages/rest_framework/views.py", line 492, in dispatch
    response = handler(request, *args, **kwargs)
  File "/usr/local/lib/python3.6/dist-packages/rest_framework/generics.py", line 192, in post
    return self.create(request, *args, **kwargs)
  File "/applications/users/views.py", line 38, in create
    self.perform_create(serializer)
  File "/applications/users/views.py", line 33, in perform_create
    settings.EMAIL.activation(self.request, context).send(to)
  File "/usr/local/lib/python3.6/dist-packages/templated_mail/mail.py", line 68, in send
    self.render()
  File "/usr/local/lib/python3.6/dist-packages/templated_mail/mail.py", line 61, in render
    template = get_template(self.template_name)
  File "/usr/local/lib/python3.6/dist-packages/django/template/loader.py", line 19, in get_template
    raise TemplateDoesNotExist(template_name, chain=chain)
django.template.exceptions.TemplateDoesNotExist: emails_templates/activation.html
Internal Server Error: /v1/users/create/
Traceback (most recent call last):
  File "/usr/local/lib/python3.6/dist-packages/django/core/handlers/exception.py", line 34, in inner
    response = get_response(request)
  File "/usr/local/lib/python3.6/dist-packages/django/core/handlers/base.py", line 115, in _get_response
    response = self.process_exception_by_middleware(e, request)
  File "/usr/local/lib/python3.6/dist-packages/django/core/handlers/base.py", line 113, in _get_response
    response = wrapped_callback(request, *callback_args, **callback_kwargs)
  File "/usr/local/lib/python3.6/dist-packages/django/views/decorators/csrf.py", line 54, in wrapped_view
    return view_func(*args, **kwargs)
  File "/usr/local/lib/python3.6/dist-packages/django/views/generic/base.py", line 71, in view
    return self.dispatch(request, *args, **kwargs)
  File "/usr/local/lib/python3.6/dist-packages/rest_framework/views.py", line 495, in dispatch
    response = self.handle_exception(exc)
  File "/usr/local/lib/python3.6/dist-packages/rest_framework/views.py", line 455, in handle_exception
    self.raise_uncaught_exception(exc)
  File "/usr/local/lib/python3.6/dist-packages/rest_framework/views.py", line 492, in dispatch
    response = handler(request, *args, **kwargs)
  File "/usr/local/lib/python3.6/dist-packages/rest_framework/generics.py", line 192, in post
    return self.create(request, *args, **kwargs)
  File "/applications/users/views.py", line 38, in create
    self.perform_create(serializer)
  File "/applications/users/views.py", line 33, in perform_create
    settings.EMAIL.activation(self.request, context).send(to)
  File "/usr/local/lib/python3.6/dist-packages/templated_mail/mail.py", line 68, in send
    self.render()
  File "/usr/local/lib/python3.6/dist-packages/templated_mail/mail.py", line 61, in render
    template = get_template(self.template_name)
  File "/usr/local/lib/python3.6/dist-packages/django/template/loader.py", line 19, in get_template
    raise TemplateDoesNotExist(template_name, chain=chain)
django.template.exceptions.TemplateDoesNotExist: emails/emails_templates/activation.html
Internal Server Error: /v1/users/create/
Traceback (most recent call last):
  File "/usr/local/lib/python3.6/dist-packages/django/core/handlers/exception.py", line 34, in inner
    response = get_response(request)
  File "/usr/local/lib/python3.6/dist-packages/django/core/handlers/base.py", line 115, in _get_response
    response = self.process_exception_by_middleware(e, request)
  File "/usr/local/lib/python3.6/dist-packages/django/core/handlers/base.py", line 113, in _get_response
    response = wrapped_callback(request, *callback_args, **callback_kwargs)
  File "/usr/local/lib/python3.6/dist-packages/django/views/decorators/csrf.py", line 54, in wrapped_view
    return view_func(*args, **kwargs)
  File "/usr/local/lib/python3.6/dist-packages/django/views/generic/base.py", line 71, in view
    return self.dispatch(request, *args, **kwargs)
  File "/usr/local/lib/python3.6/dist-packages/rest_framework/views.py", line 495, in dispatch
    response = self.handle_exception(exc)
  File "/usr/local/lib/python3.6/dist-packages/rest_framework/views.py", line 455, in handle_exception
    self.raise_uncaught_exception(exc)
  File "/usr/local/lib/python3.6/dist-packages/rest_framework/views.py", line 492, in dispatch
    response = handler(request, *args, **kwargs)
  File "/usr/local/lib/python3.6/dist-packages/rest_framework/generics.py", line 192, in post
    return self.create(request, *args, **kwargs)
  File "/applications/users/views.py", line 38, in create
    self.perform_create(serializer)
  File "/applications/users/views.py", line 33, in perform_create
    settings.EMAIL.activation(self.request, context).send(to)
  File "/usr/local/lib/python3.6/dist-packages/templated_mail/mail.py", line 68, in send
    self.render()
  File "/usr/local/lib/python3.6/dist-packages/templated_mail/mail.py", line 61, in render
    template = get_template(self.template_name)
  File "/usr/local/lib/python3.6/dist-packages/django/template/loader.py", line 19, in get_template
    raise TemplateDoesNotExist(template_name, chain=chain)
django.template.exceptions.TemplateDoesNotExist: activation.html
Internal Server Error: /v1/users/create/
Traceback (most recent call last):
  File "/usr/local/lib/python3.6/dist-packages/django/core/handlers/exception.py", line 34, in inner
    response = get_response(request)
  File "/usr/local/lib/python3.6/dist-packages/django/core/handlers/base.py", line 115, in _get_response
    response = self.process_exception_by_middleware(e, request)
  File "/usr/local/lib/python3.6/dist-packages/django/core/handlers/base.py", line 113, in _get_response
    response = wrapped_callback(request, *callback_args, **callback_kwargs)
  File "/usr/local/lib/python3.6/dist-packages/django/views/decorators/csrf.py", line 54, in wrapped_view
    return view_func(*args, **kwargs)
  File "/usr/local/lib/python3.6/dist-packages/django/views/generic/base.py", line 71, in view
    return self.dispatch(request, *args, **kwargs)
  File "/usr/local/lib/python3.6/dist-packages/rest_framework/views.py", line 495, in dispatch
    response = self.handle_exception(exc)
  File "/usr/local/lib/python3.6/dist-packages/rest_framework/views.py", line 455, in handle_exception
    self.raise_uncaught_exception(exc)
  File "/usr/local/lib/python3.6/dist-packages/rest_framework/views.py", line 492, in dispatch
    response = handler(request, *args, **kwargs)
  File "/usr/local/lib/python3.6/dist-packages/rest_framework/generics.py", line 192, in post
    return self.create(request, *args, **kwargs)
  File "/applications/users/views.py", line 38, in create
    self.perform_create(serializer)
  File "/applications/users/views.py", line 33, in perform_create
    settings.EMAIL.activation(self.request, context).send(to)
  File "/usr/local/lib/python3.6/dist-packages/templated_mail/mail.py", line 68, in send
    self.render()
  File "/usr/local/lib/python3.6/dist-packages/templated_mail/mail.py", line 61, in render
    template = get_template(self.template_name)
  File "/usr/local/lib/python3.6/dist-packages/django/template/loader.py", line 19, in get_template
    raise TemplateDoesNotExist(template_name, chain=chain)
django.template.exceptions.TemplateDoesNotExist: applications/emails/emails_templates/activation.html
Internal Server Error: /v1/users/create/
Traceback (most recent call last):
  File "/usr/local/lib/python3.6/dist-packages/django/core/handlers/exception.py", line 34, in inner
    response = get_response(request)
  File "/usr/local/lib/python3.6/dist-packages/django/core/handlers/base.py", line 115, in _get_response
    response = self.process_exception_by_middleware(e, request)
  File "/usr/local/lib/python3.6/dist-packages/django/core/handlers/base.py", line 113, in _get_response
    response = wrapped_callback(request, *callback_args, **callback_kwargs)
  File "/usr/local/lib/python3.6/dist-packages/django/views/decorators/csrf.py", line 54, in wrapped_view
    return view_func(*args, **kwargs)
  File "/usr/local/lib/python3.6/dist-packages/django/views/generic/base.py", line 71, in view
    return self.dispatch(request, *args, **kwargs)
  File "/usr/local/lib/python3.6/dist-packages/rest_framework/views.py", line 495, in dispatch
    response = self.handle_exception(exc)
  File "/usr/local/lib/python3.6/dist-packages/rest_framework/views.py", line 455, in handle_exception
    self.raise_uncaught_exception(exc)
  File "/usr/local/lib/python3.6/dist-packages/rest_framework/views.py", line 492, in dispatch
    response = handler(request, *args, **kwargs)
  File "/usr/local/lib/python3.6/dist-packages/rest_framework/generics.py", line 192, in post
    return self.create(request, *args, **kwargs)
  File "/applications/users/views.py", line 38, in create
    self.perform_create(serializer)
  File "/applications/users/views.py", line 33, in perform_create
    settings.EMAIL.activation(self.request, context).send(to)
  File "/usr/local/lib/python3.6/dist-packages/templated_mail/mail.py", line 68, in send
    self.render()
  File "/usr/local/lib/python3.6/dist-packages/templated_mail/mail.py", line 61, in render
    template = get_template(self.template_name)
  File "/usr/local/lib/python3.6/dist-packages/django/template/loader.py", line 19, in get_template
    raise TemplateDoesNotExist(template_name, chain=chain)
django.template.exceptions.TemplateDoesNotExist: emails/emails_templates/activation.html
Internal Server Error: /v1/users/create/
Traceback (most recent call last):
  File "/usr/local/lib/python3.6/dist-packages/django/core/handlers/exception.py", line 34, in inner
    response = get_response(request)
  File "/usr/local/lib/python3.6/dist-packages/django/core/handlers/base.py", line 115, in _get_response
    response = self.process_exception_by_middleware(e, request)
  File "/usr/local/lib/python3.6/dist-packages/django/core/handlers/base.py", line 113, in _get_response
    response = wrapped_callback(request, *callback_args, **callback_kwargs)
  File "/usr/local/lib/python3.6/dist-packages/django/views/decorators/csrf.py", line 54, in wrapped_view
    return view_func(*args, **kwargs)
  File "/usr/local/lib/python3.6/dist-packages/django/views/generic/base.py", line 71, in view
    return self.dispatch(request, *args, **kwargs)
  File "/usr/local/lib/python3.6/dist-packages/rest_framework/views.py", line 495, in dispatch
    response = self.handle_exception(exc)
  File "/usr/local/lib/python3.6/dist-packages/rest_framework/views.py", line 455, in handle_exception
    self.raise_uncaught_exception(exc)
  File "/usr/local/lib/python3.6/dist-packages/rest_framework/views.py", line 492, in dispatch
    response = handler(request, *args, **kwargs)
  File "/usr/local/lib/python3.6/dist-packages/rest_framework/generics.py", line 192, in post
    return self.create(request, *args, **kwargs)
  File "/applications/users/views.py", line 38, in create
    self.perform_create(serializer)
  File "/applications/users/views.py", line 33, in perform_create
    settings.EMAIL.activation(self.request, context).send(to)
  File "/usr/local/lib/python3.6/dist-packages/templated_mail/mail.py", line 68, in send
    self.render()
  File "/usr/local/lib/python3.6/dist-packages/templated_mail/mail.py", line 61, in render
    template = get_template(self.template_name)
  File "/usr/local/lib/python3.6/dist-packages/django/template/loader.py", line 19, in get_template
    raise TemplateDoesNotExist(template_name, chain=chain)
django.template.exceptions.TemplateDoesNotExist: ./emails_templates/activation.html
Bad Request: /v1/users/create/
Internal Server Error: /v1/users/create/
Traceback (most recent call last):
  File "/usr/local/lib/python3.6/dist-packages/django/core/handlers/exception.py", line 34, in inner
    response = get_response(request)
  File "/usr/local/lib/python3.6/dist-packages/django/core/handlers/base.py", line 115, in _get_response
    response = self.process_exception_by_middleware(e, request)
  File "/usr/local/lib/python3.6/dist-packages/django/core/handlers/base.py", line 113, in _get_response
    response = wrapped_callback(request, *callback_args, **callback_kwargs)
  File "/usr/local/lib/python3.6/dist-packages/django/views/decorators/csrf.py", line 54, in wrapped_view
    return view_func(*args, **kwargs)
  File "/usr/local/lib/python3.6/dist-packages/django/views/generic/base.py", line 71, in view
    return self.dispatch(request, *args, **kwargs)
  File "/usr/local/lib/python3.6/dist-packages/rest_framework/views.py", line 495, in dispatch
    response = self.handle_exception(exc)
  File "/usr/local/lib/python3.6/dist-packages/rest_framework/views.py", line 455, in handle_exception
    self.raise_uncaught_exception(exc)
  File "/usr/local/lib/python3.6/dist-packages/rest_framework/views.py", line 492, in dispatch
    response = handler(request, *args, **kwargs)
  File "/usr/local/lib/python3.6/dist-packages/rest_framework/generics.py", line 192, in post
    return self.create(request, *args, **kwargs)
  File "/applications/users/views.py", line 38, in create
    self.perform_create(serializer)
  File "/applications/users/views.py", line 33, in perform_create
    settings.EMAIL.activation(self.request, context).send(to)
  File "/usr/local/lib/python3.6/dist-packages/djoser/conf.py", line 18, in __getattribute__
    val = import_string(val)
  File "/usr/local/lib/python3.6/dist-packages/django/utils/module_loading.py", line 17, in import_string
    module = import_module(module_path)
  File "/usr/lib/python3.6/importlib/__init__.py", line 126, in import_module
    return _bootstrap._gcd_import(name[level:], package, level)
  File "<frozen importlib._bootstrap>", line 994, in _gcd_import
  File "<frozen importlib._bootstrap>", line 971, in _find_and_load
  File "<frozen importlib._bootstrap>", line 953, in _find_and_load_unlocked
ModuleNotFoundError: No module named 'emails.emails_services'
